Workbook

Sheet Application Design
A1: Application Design Sheet
A2: Magnetic Conveyor
A3: Quote # | B3: 61401 | D3: Job # | E3: 32425
A4: Customer | B4: G-Fab | D4: Designer | E4: Frank Neufeld
A6: Specification | C6: MC3 Standard
B7: If customer specification, provide reference brands, part numbers, as applicable
A13: Special Requirements
B14: Ex. customer title blocks, extensive manuals and etc.
A19: Loading/Unloading of Conveyor
B20: Describe how conveyor is loaded (from the side, from the tail end, is the load moving at high velocity, how the load is being dumped,
B21: is conveyor loaded with shuffle trays, shaker conveyor and etc.)
B22: All inputs (conveyors, shuffle trays, chutes and etc.) need to be modeled in our designs
B23: Describe where and how conveyor unloads (in the bin, into another conveyor and etc.)
A28: Environmental Factors | C28: Outdoors | E28: =IF(C28="High Temperature","Need venting in conveyor body and do not use if above 150 C",IF(C28="Outdoors","Need washdown motor/control box, SS fasteners, SS conveyor body",IF(C28="Hazardous","Need explosion proof motor? What class and division?",""))) -> Need washdown motor/control box, SS fasteners, SS conveyor body
A30: Customer's Machine Tool Info
B31: Make
B32: Model
B33: Process | E33: =IF(C33="Turning","Use magnetic only if turning chips are short and not stringers","")
B34: Does Eng. need to send drawing to Estimating to create quote template?
A36: Material Data
B37: Material | C37: Parts | E37: =IF(C37="Parts","If parts and using neo magnets - use manganese cover","") -> If parts and using neo magnets - use manganese cover
B38: Material type | C38: Steel | E38: =IF(C38="Aluminum","Cannot magnitize - should not be magnetic conveyor", IF(C38="Stainless Steel","Cannot magnitize - should not be magnetic conveyor",""))
B39: Chip Type | C39: Small | E39: =IF(C39="Stringers","Magnetic conveyor is a poor option due to magnet bridging", IF(C39="Bird Nests","Magnetic conveyor is a poor option due to magnet bridging",""))
B40: Material Size (THK x WD x LG) | C40: Thickness (in.) | E40: Hint: make sure pitch of magnets is larger than part size,
C41: Width (in.) | E41: otherwise bridging can occurr
C42: Length (in.)
B43: Density of material (lbs/in3) | C43: 0.28 | E43: Cast Iron: 0.26 Steel: 0.28
B44: Weight of individual part (lbs)
B45: Material drop height (in) | E45: Hint: if small chips then height does not matter. If parts,
E46: then fall and height matter. If the part is light, then we can use
E47: thicker infeed cover. If the part is heavy (ounces and pounds),
E48: then we need other considerations (chute, manganese cover, etc.)
B49: Throughput of conv. (lbs/hr) | C49: 12000
B50: Feed rate of machine tool (part/min)
B51: Scrap bin size (HT x WD x LG) | D51: Fill frequency
B52: Temperature of parts | C52: Ambient | E52: =IF(C52="Red Hot","Magnetic conveyor is a poor choice","")
B54: Fluid Present | C54: No
B55: Fluid Type | E55: =IF(C55="Oil Based","Require SS rigidized cover",IF(C55="Water Soluble","Find out if there is oil build-up in the water, from ",""))
E56: =IF(C55="Water Soluble","continuous seeping of oil into water. If yes, then need","")
E57: =IF(C55="Water Soluble","SS rigidized cover. If not, then regular SS cover","")
...

Sheet Navigator
A1: USE IF CONVEYING CHIPS/SWARF
A4: USE IF CONVEYING PARTS/SCRAP
A7: RETURN TO APPLICATION DESIGN

Sheet Chips.Swarf-Calculator
A1: USE IF CONVEYING CHIPS
A3: Only yellow cells require input from Designer | E3: RETURN TO APPLICATION DESIGN
A5: MAGNET INPUT SECTION
A6: Infeed Length | B6: ='Application Design'!C62 -> 119.375 | C6: in
A7: Incline Deg. | B7: ='Application Design'!C64 -> 75 | C7: degrees
A8: Discharge Height | B8: ='Application Design'!C63 -> 336 | C8: in
A9: Discharge Length | B9: 22 | C9: in | D9: Hint: 22" is standard
A10: Magnet Width | B10: ='Application Design'!C66 -> 28 | C10: in
A11: Chain Weight (C2060) | B11: 2 | C11: lb/ft
A12: Belt Speed | B12: ='Application Design'!C74 -> 70 | C12: ft/min
A13: Magnet Centers | B13: ='Application Design'!C69 -> 12 | C13: in
A14: Load Per Hr. | B14: ='Application Design'!C49 -> 12000 | C14: lb/hr
A15: Removal/Bar | B15: 1.5 | C15: lbs | D15: USE TABLES
A16: MAGNET CALCULATION SECTION
A17: Incline Length | B17: =IF(B8=0, 0, B8/SIN(B7*PI()/180)) -> 347.8528 | C17: in
A18: Incline Run | B18: =IF(B8=0, 0, B8/1/TAN(B7*PI()/180)) -> 90.030929 | C18: in
A19: Horizontal Length of Conveyor | B19: =B6+B18+B9 -> 231.40593 | C19: in
A20: Path Length of Conveyor | B20: =(B6+B17+B9)/12 -> 40.768983 | C20: ft
A21: Belt Length | B21: =(((B6+B17+B9)*2)/12) -> 81.537966 | C21: ft
A22: Magnet Weight | B22: =0.22+(B10*0.5312) -> 15.0936 | C22: ea
A23: Belt Weight Per Foot | B23: =(B11)+(B22*B28/B21) -> 16.908489 | C23: lb/ft
A24: Belt Pull Friction | B24: =(B23*B21*B43) -> 206.80257 | C24: lb
A25: Belt Pull Gravity | B25: =((B17/12*B23)*SIN(B7*PI()/180)) -> 473.43768 | C25: lb
A26: Chip Load On Bed | B26: =(B15*B28/2) -> 60.403475 | C26: lbs
A27: Total Load Per Cycle | B27: =SUM(B24:B26) -> 740.64372 | C27: lb
A28: Total QTY Of Magnets | B28: =((B21*12/B13)-1) -> 80.537966
A29: Magnet Cycle Time | B29: =(B20/B12)*(B13/12) -> 0.58241404 | C29: min
A30: Removal Rate Of Single Bar | B30: =(B15/B29)*60 -> 154.52924 | C30: lbs/hr
A31: Throughput Of Conveyor | B31: =(B30*B28)/2 -> 6222.7354 | C31: lbs/hr
A32: Achieved Throughput Margin | B32: =B31/B14 -> 0.51856128 | D32: Hint: must be equal to or greater than 1.5
A33: DRIVE CALCULATION SECTION
A34: Pitch of chain | B34: 1.5 | C34: in
A35: Number of used teeth on sprocket | B35: 14
A36: Efficiency of chain drive | B36: 0.8
A37: Running efficiency of worm reducer | B37: 0.76
A38: Starting efficiency of worm reducer | B38: 0.4
A39: Lead (Circumference of sprocket) | B39: =B34*B35 -> 21 | C39: in/rev
A40: Running Torque | B40: =(B27*B34)/(B36*B37) -> 1827.246 | C40: in-lb | E40: RETURN TO APPLICATION DESIGN
A41: Starting Torque | B41: =(B27*B34)/(B38*B36) -> 3471.7675 | C41: in-lb
A42: Required output torque of GM | B42: =B41*B48 -> 5207.6512 | C42: in-lb
...

Sheet Parts.Scrap-Calculator
A1: USE IF CONVEYING PARTS/SCRAP
A3: Only yellow cells require input from Designer | F3: RETURN TO APPLICATION DESIGN
A5: MAGNET INPUT SECTION
A6: Infeed length | B6: ='Application Design'!C62 -> 119.375 | C6: in
A7: Incline Deg. | B7: ='Application Design'!C64 -> 75 | C7: degrees
A8: Discharge Height | B8: ='Application Design'!C63 -> 336 | C8: in
A9: Discharge Length | B9: 22 | C9: in | D9: Hint: 22" is standard
A10: Magnet Width | B10: ='Application Design'!C66 -> 28 | C10: in
A11: Chain Weight (C2060) | B11: 2 | C11: lb/ft
A12: Magnet Centers | B12: ='Application Design'!C69 -> 12 | C12: in
A13: Desired parts per minute | B13: ='Application Design'!C50 -> 0 | C13: part/min
A14: Weight of each part | B14: ='Application Design'!C44 -> 0 | C14: lbs
A15: Parts per each magnet bar | B15: 2 | C15: parts | D15: USE TABLES | E15: Hint: consider size of part and removal lbs per bar
A16: MAGNET CALCULATION SECTION
A17: Magnet Frequency | B17: =(B23/B31/B30) -> 0.014463093 | C17: min
A18: Needed Belt Speed (Minimum) | B18: =(B13/B15)*(B12/12) -> 0 | C18: ft/min | D18: Hint: ensure that selected speed is higher than needed
A19: Incline Length | B19: =IF(B8=0, 0, B8/SIN(B7*PI()/180)) -> 347.8528 | C19: in
A20: Incline Run | B20: =IF(B8=0, 0, B8/1/TAN(B7*PI()/180)) -> 90.030929 | C20: in
A21: Horizontal Length Of Conveyor | B21: =B6+B20+B9 -> 231.40593 | C21: in
A22: Path Length Of Conveyor | B22: =(B6+B19+B9)/12 -> 40.768983 | C22: ft
A23: Belt Length | B23: =(((B6+B19+B9)*2)/12) -> 81.537966 | C23: ft
A24: Magnet Weight | B24: =0.22+(B10*0.5312) -> 15.0936 | C24: ea
A25: Weight Per Foot | B25: =B11+(B24*B30/B23) -> 16.908489 | C25: lb/ft
A26: Belt Pull Friction | B26: =(B25*B23*B34) -> 275.73676 | C26: lb
A27: Belt Pull Gravity | B27: =((B19/12*B25)*SIN(B7*PI()/180)) -> 473.43768 | C27: lb
A28: Part Load On Bed | B28: =(B15*B14)*(B30/2) -> 0 | C28: lbs
A29: Total Load Per Cycle | B29: =SUM(B26:B28) -> 749.17444 | C29: lb
A30: Total QTY Of Magnets | B30: =(((B23*12)/B12)-1) -> 80.537966
A31: Selected Belt Speed | B31: ='Application Design'!C74 -> 70 | C31: ft/min
A32: Achieved throughput margin | B32: =B31/B18 -> #DIV/0! | D32: Hint: must be equal to or greater than 1.25
A33: DRIVE CALCULATION SECTION
A34: Coefiecent of Friction: | B34: 0.2 | D34: Steel on UHMW
A35: TOTAL BELT WEIGHT: | B35: =(B23*B25) -> 1378.6838 | C35: lbs
A36: Starting belt pull | B36: =100 -> 100 | C36: lbs
A37: total belt pull | B37: =(B36+B29) -> 849.17444 | C37: lbs
A38: Head sprocket pitch diameter | B38: 4.5 | C38: in
A39: Desired safety factor (torque based) | B39: 2
A40: Running torque | B40: =(B37*(B38/2)) -> 1910.6425 | C40: in/lbs
A41: Total Torque Requirement | B41: =B40*B39 -> 3821.285 | C41: in/lbs
A42: Pitch of chain | B42: 1 | C42: in
...

Sheet Reference Tables
A1: REFERENCE TABLES
A4: Single | B4: Magnet Type | C4: Lbs/magnet | D4: Efficiency | E4: Actual lbs/bar
B5: 2.5" Ceramic 5 | C5: 0.1 | D5: 0.8 | E5: =C5*D5 -> 0.08
B6: 3.5" Ceramic 5 | C6: 0.126 | D6: 0.8 | E6: =C6*D6 -> 0.1008
B7: 2" Neo 35-50 | C7: 0.298 | D7: 0.8 | E7: =C7*D7 -> 0.2384
A8: Combination | B8: Magnet Width | C8: Lbs/Bar | D8: Hint #1: When scrap part weighs above 1lb each, use Neo Magnets
B9: 12" Ceramic 5 | C9: =(2*E6)+(2*E5) -> 0.3616
B10: 12" w/ (1) Neo | C10: =(2*E6)+E5+E7 -> 0.52 | D10: Hint #2: If conveying parts, consider weight of the part and size
B11: 12" w/ (2) Neo | C11: =(2*E7)+(3*E5) -> 0.7168 | D11: in selection of magnets
B12: 12" w/ (3) Neo | C12: =(3*E7)+E6+E5 -> 0.896
B13: 12" w/ (4) Neo | C13: =(4*E7)+E6 -> 1.0544 | D13: Hint #3: If parts are odd shaped or have minimal surface contact,
B14: 12" w/ (5) Neo | C14: =(5*E7) -> 1.192 | D14: use multiple Neos
B15: Magnet Width | C15: Lbs/Bar
B16: 15" Ceramic 5 | C16: =(6*E5) -> 0.48
B17: 15" w/ (1) Neo | C17: =(3*E6)+E5+E7 -> 0.6208
B18: 15" w/ (2) Neo | C18: =(2*E7)+(3*E5)+E6 -> 0.8176
B19: 15" w/ (3) Neo | C19: =(3*E7)+E6+(2*E5) -> 0.976
B20: 15" w/ (4) Neo | C20: =(4*E7)+(2*E6) -> 1.1552
B21: 15" w/ (5) Neo | C21: =(5*E7)+(2*E5) -> 1.352
B22: Magnet Width | C22: Lbs/Bar
B23: 18" Ceramic 5 | C23: =(3*E5)+(3*E6) -> 0.5424
B24: 18" w/ (1) Neo | C24: =(5*E5)+E6+E7 -> 0.7392
B25: 18" w/ (2) Neo | C25: =(2*E7)+(4*E6) -> 0.88
B26: 18" w/ (3) Neo | C26: =(3*E7)+(2*E5)+(2*E6) -> 1.0768
B27: 18" w/ (4) Neo | C27: =(4*E7)+(4*E5) -> 1.2736
B28: Magnet Width | C28: Lbs/Bar | D28: RETURN TO APPLICATION DESIGN
B29: 24" Ceramic 5 | C29: =(4*E5)+(4*E6) -> 0.7232
B30: 24" w/ (1) Neo | C30: =(6*E5)+E7+(2*E6) -> 0.92 | D30: RETURN TO CHIPS/SWARF CALCULATOR
B31: 24" w/ (2) Neo | C31: =(2*E7)+(5*E6)+E5 -> 1.0608
B32: 24" w/ (3) Neo | C32: =(3*E7)+(3*E6)+(3*E5) -> 1.2576 | D32: RETURN TO PARTS CALCULATOR
B33: 24" w/ (4) Neo | C33: =(4*E7)+(5*E5)+E6 -> 1.4544
